Workbook

Sheet AAV10281
A1: 重庆尚上服饰有限公司
A2: 款式工序表
A3: 打印日期：2025-08-23 11:36:43
A4: 生产制单号： | B4: AAV10281
A5: 客 户： | B5: 鹿岛
A6: 客户款号： | B6: AAV10281
A7: 款式描述： | B7: 梭织长裤，斜插袋、贴风琴肶袋、平角袋盖，左右后机头，本布腰、多针包橡筋，穿腰绳
A8: 品质标准：
A9: 数 量：
A10: 车缝时间： | B10: =SUM(G38:G50,G52:G60,G62:G69,G73:G75,G79:G98) -> 1393.3
A11: 车缝10.5H台产： | B11: =10.5*60*60/B10 -> 27.129836
A12: 裁床10H台产：
A13: 尾部10H台产
A14: 裁床单价：
A15: 车缝单价：
A16: 后道单价：
A17: 总 单 价：
A18: 平均秒值：
A19: 分 析 员： | B19: QLY-钱玲燕
A20: 工序号 | B20: 工序名称 | E20: 机器类型 | F20: 基础时间 | G20: GST时间 | H20: 工序等级 | I20: 小时目标
B21: 1-裁床 | D21: 1-裁床
B22: 松面布 | C22: 1 | D22: 松布机松面布*1.4794 | E22: 松布机 | F22: 7.3 | G22: 8.2 | H22: E2 | I22: 439
A23: 155 | B23: 拉面布 | C23: 2 | D23: 拉布机拉面布*1.4794 | E23: 拉布机 | F23: 19.1 | G23: 21.5 | H23: E3 | I23: 167
A24: 2 | B24: 裁面布 | C24: 3 | D24: 手工裁剪面布*13 | E24: 电剪刀 | F24: 12.2 | G24: 13.7 | H24: D4 | I24: 263
A25: 5 | B25: 面布分包 | C25: 4 | D25: 手工面布分包*13 | E25: 手工 | F25: 15.7 | G25: 17.3 | H25: E2 | I25: 208
A26: 16 | B26: 打编号 | C26: 5 | D26: 手工打编号*13 | E26: 手工 | F26: 15.5 | G26: 17.1 | H26: E2 | I26: 211
A27: 170 | B27: 面布验片 | C27: 6 | D27: 手工面布验片*9 | E27: 手工 | F27: 19.7 | G27: 21.8 | H27: E3 | I27: 165
A28: 6 | B28: 拉袋布 | C28: 7 | D28: 拉布机拉袋布*0.0813 | E28: 拉布机 | F28: 0.9 | G28: 1 | H28: E3 | I28: 3600
A29: 9 | B29: 裁袋布 | C29: 8 | D29: 电脑裁剪袋布*2 | E29: 电脑裁床 | F29: 1 | G29: 1.1 | H29: D4 | I29: 3273
A30: 3 | B30: 袋布分包 | C30: 9 | D30: 手工袋布分包*2（大包） | E30: 手工 | F30: 0.8 | G30: 0.9 | H30: E2 | I30: 4000
A31: 8 | B31: 拉衬布 | C31: 10 | D31: 拉衬布*0.0565 | E31: 拉布机 | F31: 0.6 | G31: 0.7 | H31: E2 | I31: 5143
A32: 4 | B32: 裁剪衬布 | C32: 11 | D32: 裁剪衬布*2 | E32: 电脑裁床 | F32: 0.5 | G32: 0.5 | H32: D4 | I32: 7200
A33: 7 | B33: 衬布分包 | C33: 12 | D33: 衬布分包*2（大包） | E33: 手工 | F33: 0.3 | G33: 0.3 | H33: E1 | I33: 12000
A34: 15 | B34: 中烫烫袋盖衬*2 | C34: 13 | D34: 中烫烫袋盖衬*2 | E34: 中烫（气烫） | F34: 11.1 | G34: 12.5 | H34: E2 | I34: 288
A35: 10 | B35: 切脚口车侧缝挂耳捆条 | C35: 14 | D35: 切脚口车侧缝挂耳捆条*0.005 | E35: 切捆条机 | F35: 0.4 | G35: 0.4 | H35: E3 | I35: 9000
A36: 11 | B36: 下裁片
B37: 2-腰头 | D37: 2-腰头
A38: 14 | B38: 缩水腰头橡筋、脚口橡筋绳/米 | C38: 15 | D38: 缩水腰头橡筋、脚口橡筋绳/米 | E38: 蒸箱 | F38: 1.4 | G38: 1.4 | H38: E1 | I38: 2571
A39: 21 | B39: 量剪腰宽橡筋 | C39: 16 | D39: 量剪腰宽橡筋*1 | E39: 手工 | F39: 3.6 | G39: 4 | H39: E1 | I39: 900
A40: 22 | B40: 拼接腰头橡筋 | C40: 17 | D40: 拼接腰头橡筋*1 | E40: 电脑平车 | F40: 7 | G40: 7.8 | H40: D4 | I40: 462
...

Sheet Sheet1
A1: 小组 | B1: 款号 | C1: 床次 | D1: 颜色 | E1: 尺码 | F1: 员工编号 | G1: 员工名称 | H1: 工序序号 | I1: 工序 | J1: 数量 | K1: 生产时间 | L1: 工序 | M1: 求和项:数量
A2: 隆昌缝制八组 | B2: AAV10276 | C2: 2/820 | D2: 军绿色 | E2: M | F2: 100567086 | G2: 李德艳 | H2: 91 | I2: 拆脚口 | J2: 12 | K2: 45898 | L2: 拆脚口 | M2: 804
A3: 隆昌缝制八组 | B3: AAV10276 | C3: 2/820 | D3: 军绿色 | E3: M | F3: 100567091 | G3: 肖慈美 | H3: 91 | I3: 拆脚口 | J3: 7 | K3: 45898 | L3: 车脚口 | M3: 348
A4: 隆昌缝制一组 | B4: AAV10276 | C4: 3/820 | D4: 军绿色 | E4: 2XL | F4: 100566874 | G4: 李上容 | H4: 91 | I4: 拆脚口 | J4: 5 | K4: 45896 | L4: 总计 | M4: 1152
A5: 隆昌缝制八组 | B5: AAV10276 | C5: 3/820 | D5: 军绿色 | E5: M | F5: 100567011 | G5: 王自淑 | H5: 91 | I5: 拆脚口 | J5: 8 | K5: 45898
A6: 隆昌缝制一组 | B6: AAV10276 | C6: 8/900 | D6: 军绿色 | E6: XL | F6: 100566874 | G6: 李上容 | H6: 91 | I6: 拆脚口 | J6: 13 | K6: 45896
A7: 隆昌缝制九组 | B7: AAV10276 | C7: 3/820 | D7: 军绿色 | E7: L | F7: 100564052 | G7: 张兴宏 | H7: 91 | I7: 拆脚口 | J7: 9 | K7: 45898
A8: 隆昌缝制一组 | B8: AAV10276 | C8: 11/903 | D8: 军绿色 | E8: M | F8: 100566398 | G8: 卢光霞 | H8: 91 | I8: 拆脚口 | J8: 14 | K8: 45896
A9: 隆昌缝制一组 | B9: AAV10276 | C9: 6/901 | D9: 军绿色 | E9: XL | F9: 100566874 | G9: 李上容 | H9: 91 | I9: 拆脚口 | J9: 12 | K9: 45896
A10: 隆昌缝制二组 | B10: AAV10276 | C10: 2/820 | D10: 军绿色 | E10: XL | F10: 100567060 | G10: 杨蕙嘉 | H10: 91 | I10: 拆脚口 | J10: 12 | K10: 45896
A11: 隆昌缝制二组 | B11: AAV10276 | C11: 12/903 | D11: 军绿色 | E11: XL | F11: 100567060 | G11: 杨蕙嘉 | H11: 91 | I11: 拆脚口 | J11: 14 | K11: 45898
A12: 隆昌缝制四组 | B12: AAV10276 | C12: 14/902 | D12: 军绿色 | E12: XL | F12: 100565622 | G12: 梁绍坤 | H12: 91 | I12: 拆脚口 | J12: 14 | K12: 45896
A13: 隆昌缝制八组 | B13: AAV10276 | C13: 10/902 | D13: 军绿色 | E13: M | F13: 100567011 | G13: 王自淑 | H13: 91 | I13: 拆脚口 | J13: 7 | K13: 45898
A14: 隆昌缝制四组 | B14: AAV10276 | C14: 3/820 | D14: 军绿色 | E14: 2XL | F14: 100565622 | G14: 梁绍坤 | H14: 91 | I14: 拆脚口 | J14: 17 | K14: 45896
A15: 隆昌缝制二组 | B15: AAV10276 | C15: 8/900 | D15: 军绿色 | E15: XL | F15: 100567060 | G15: 杨蕙嘉 | H15: 91 | I15: 拆脚口 | J15: 23 | K15: 45896
A16: 隆昌缝制九组 | B16: AAV10276 | C16: 7/900 | D16: 军绿色 | E16: M | F16: 100564060 | G16: 吕麟英 | H16: 91 | I16: 拆脚口 | J16: 14 | K16: 45898
... A102: 隆昌缝制四组 | B102: AAV10276 | C102: 7/900 | D102: 军绿色 | E102: XL | F102: 100566371 | G102: 陈远惠 | H102: 92 | I102: 车脚口 | J102: 14 | K102: 45896
J103: =SUBTOTAL(9,J80:J96) -> 210
J113: =SUBTOTAL(9,J104:J112) -> 0

Sheet Sheet2
A1: 班组 | B1: 款号 | C1: 颜色 | D1: 尺码 | E1: 床次 | F1: 工序序号 | G1: 工序名称 | H1: 数量 | I1: 员工工号 | J1: 员工姓名 | K1: 日期 | L1: 工序名称 | M1: 求和项:数量
A2: 隆昌缝制五组 | B2: AAV10281 | C2: 正黑色 | D2: L | F2: 65 | G2: 五线对位合后浪*1 | H2: 88 | I2: 00116 | J2: 何贵香 | K2: 45908 | L2: #平车固定袋布于腰口及侧方连订前袋上端打枣位 | M2: 316
A3: 隆昌缝制五组 | B3: AAV10281 | C3: 正黑色 | D3: L | F3: 76 | G3: 手工翻裤子 | H3: 137 | I3: 00240 | J3: 曾星淑 | K3: 45908 | L3: 拆腰头橡筋固定线 | M3: 361
A4: 隆昌缝制五组 | B4: AAV10281 | C4: 正黑色 | D4: S | F4: 58 | G4: 手工实样点肶袋及袋盖位 | H4: 46 | I4: 0228 | J4: 李金玲 | K4: 45908 | L4: 打腰头后中枣*1 | M4: 1313
A5: 隆昌缝制五组 | B5: 15C0196-翻单 | C5: 黑色 | D5: 2XL | E5: 42/563 | F5: 91 | G5: 打腰头后中枣*1 | H5: 32 | I5: 100565524 | J5: 黄显菊 | K5: 45908 | L5: 带线刀车车肶袋盖净样线 | M5: 262
A6: 隆昌缝制五组 | B6: AAV10281 | C6: 军绿色 | D6: L | E6: 13 | F6: 57 | G6: 手工翻两角袋盖*2 | H6: 74 | I6: 100566560 | J6: 苏小林 | K6: 45908 | L6: 挂片 | M6: 291
A7: 隆昌缝制五组 | B7: 15C0196-翻单 | C7: 酒红 | D7: L | E7: 97/949 | F7: 30 | G7: 自动模板运侧袋盖暗线连激光止口*2 | H7: 416 | I7: 100566810 | J7: 赵素英 | K7: 45908 | L7: 平车包脚口绳车脚口宽线 | M7: 363
A8: 隆昌缝制五组 | B8: AAV10281 | C8: 正黑色 | D8: 2XL | F8: 52 | G8: 四线落底袋布合前袋布一周 | H8: 109 | I8: 1209 | J8: 曾本聪 | K8: 45908 | L8: 平车订后中尺码标*1 | M8: 361
A9: 隆昌缝制五组 | B9: AAV10281 | C9: 正黑色 | D9: XL | F9: 49 | G9: 平车固定挂耳于前侧下脚位 | H9: 1 | I9: 1789 | J9: 廖方萍 | K9: 45908 | L9: 平车订洗标于左后侧缝 | M9: 341
A10: 隆昌缝制五组 | B10: AAV10281 | C10: 正黑色 | D10: L | F10: 77 | G10: 五线对位合侧缝 | H10: 63 | I10: 2724 | J10: 张世勤 | K10: 45908 | L10: 平车跟烫痕压肶袋风琴边三边明线 | M10: 240
A11: 隆昌缝制五组 | B11: AAV10281 | C11: 正黑色 | D11: L | F11: 79 | G11: 平车排肶袋口一段 | H11: 7 | I11: 4494 | J11: 田秀蓉 | K11: 45908 | L11: 平车固定挂耳于前侧下脚位 | M11: 341
A12: 隆昌缝制五组 | B12: AAV10281 | C12: 正黑色 | D12: M | F12: 55 | G12: 平车压后机头明线 | H12: 3 | I12: 9189 | J12: 陈良 | K12: 45908 | L12: 平车合底浪骨位一段*1 | M12: 321
A13: 隆昌缝制五组 | B13: AAV10281 | C13: 正黑色 | D13: S | F13: 59 | G13: 平车转角贴肶袋三边明线连转角重叠固定袋口两端*2 | H13: 5 | I13: 9481 | J13: 聂富坤 | K13: 45908 | L13: 平车合后浪后机头一段*1 | M13: 346
A14: 隆昌缝制五组 | B14: AAV10281 | C14: 正黑色 | D14: M | F14: 65 | G14: 五线对位合后浪*1 | H14: 32 | I14: 00116 | J14: 何贵香 | K14: 45908 | L14: 平车开骨落橡筋包固腰头位*2 | M14: 588
A15: 隆昌缝制五组 | B15: AAV10281 | C15: 正黑色 | D15: S | F15: 18 | G15: 带线刀车车肶袋盖净样线 | H15: 109 | I15: 00137 | J15: 袁祖平 | K15: 45908 | L15: 平车落肶袋盖连压袋盖线*2 | M15: 325
A16: 隆昌缝制五组 | B16: AAV10281 | C16: 军绿色 | D16: L | E16: 13 | F16: 25 | G16: 手工点橡筋中位*1 | H16: 5 | I16: 100565074 | J16: 谢本习 | K16: 45908 | L16: 平车落前袋口暗线 | M16: 519
A17: 隆昌缝制五组 | B17: AAV10281 | C17: 军绿色 | D17: M | E17: 14 | F17: 36 | G17: 平车开骨落橡筋包固腰头位*2 | H17: 76 | I17: 100565074 | J17: 谢本习 | K17: 45908 | L17: 平车落前袋口暗线连压暗边线 | M17: 793
A18: 隆昌缝制五组 | B18: 15C0196-翻单 | C18: 黑色 | D18: S | E18: 66/871 | F18: 91 | G18: 打腰头后中枣*1 | H18: 18 | I18: 100565524 | J18: 黄显菊 | K18: 45908 | L18: 平车排肶袋口一段 | M18: 407
A19: 隆昌缝制五组 | B19: AAV10281 | C19: 军绿色 | D19: S | E19: 14 | F19: 45 | G19: 平车收肶袋角省位 | H19: 74 | I19: 100566960 | J19: 罗智忠 | K19: 45908 | L19: 平车上腰头暗线 | M19: 342
A20: 隆昌缝制五组 | B20: AAV10281 | C20: 正黑色 | D20: 2XL | F20: 75 | G20: 平车折压肶袋盖明线 | H20: 45 | I20: 2269 | J20: 胡小英 | K20: 45908 | L20: 平车收肶袋角省位 | M20: 240
A21: 隆昌缝制五组 | B21: AAV10281 | C21: 正黑色 | D21: L | F21: 42 | G21: 拆腰头橡筋固定线 | H21: 137 | I21: 00240 | J21: 曾星淑 | K21: 45908 | L21: 平车压后机头明线 | M21: 341
A22: 隆昌缝制五组 | B22: AAV10281 | C22: 正黑色 | D22: L | F22: 58 | G22: 手工实样点肶袋及袋盖位 | H22: 78 | I22: 021 | J22: 代云霞 | K22: 45908 | L22: 平车压肶袋盖三边明线 | M22: 286
A23: 隆昌缝制五组 | B23: AAV10281 | C23: 正黑色 | D23: 2XL | E23: 12 | F23: 36 | G23: 平车开骨落橡筋包固腰头位*2 | H23: 7 | I23: 100565074 | J23: 谢本习 | K23: 45908 | L23: 平车运肶袋盖两边暗线 | M23: 205
A24: 隆昌缝制五组 | B24: AAV10281 | C24: 正黑色 | D24: 2XL | E24: 11 | F24: 50 | G24: 平车落前袋口暗线连压暗边线 | H24: 104 | I24: 100565514 | J24: 曾星淑 | K24: 45908 | L24: 平车折订左手心袋布腰口橡筋挂耳连剪断 | M24: 316
A25: 隆昌缝制五组 | B25: 15C0196-翻单 | C25: 黑色 | D25: XL | E25: 42/563 | F25: 91 | G25: 打腰头后中枣*1 | H25: 52 | I25: 100565524 | J25: 黄显菊 | K25: 45908 | L25: 平车折压肶袋盖明线 | M25: 334
A26: 隆昌缝制五组 | B26: 15C0196-翻单 | C26: 黑色 | D26: XS | E26: 42/563 | F26: 91 | G26: 打腰头后中枣*1 | H26: 65 | I26: 100565524 | J26: 黄显菊 | K26: 45908 | L26: 平车转角贴肶袋三边明线连转角重叠固定袋口两端*2 | M26: 325
A27: 隆昌缝制五组 | B27: AAV10281 | C27: 军绿色 | D27: 2XL | E27: 14 | F27: 57 | G27: 手工翻两角袋盖*2 | H27: 43 | I27: 100566560 | J27: 苏小林 | K27: 45908 | L27: 三线转角锁侧袋布三边散口 | M27: 262
A28: 隆昌缝制五组 | B28: AAV10281 | C28: 军绿色 | D28: XL | E28: 14 | F28: 45 | G28: 平车收肶袋角省位 | H28: 60 | I28: 100566960 | J28: 罗智忠 | K28: 45908 | L28: 实样折烫肶袋口连折烫三边风琴边、袋止口并画袋角省位 | M28: 247
A29: 隆昌缝制五组 | B29: AAV10281 | C29: 正黑色 | D29: M | F29: 120 | G29: 中查 | H29: 126 | I29: 1393 | J29: 李明玉 | K29: 45908 | L29: 手工点橡筋中位*1 | M29: 588
A30: 隆昌缝制五组 | B30: AAV10281 | C30: 军绿色 | D30: L | F30: 48 | G30: 平车折订左手心袋布腰口橡筋挂耳连剪断 | H30: 23 | I30: 1789 | J30: 廖方萍 | K30: 45908 | L30: 手工点腰头位 | M30: 342
A31: 隆昌缝制五组 | B31: AAV10281 | C31: 正黑色 | D31: L | F31: 56 | G31: 平车订洗标于左后侧缝 | H31: 66 | I31: 1789 | J31: 廖方萍 | K31: 45908 | L31: 手工翻裤子 | M31: 361
A32: 隆昌缝制五组 | B32: AAV10281 | C32: 正黑色 | D32: L | F32: 55 | G32: 平车压后机头明线 | H32: 66 | I32: 1789 | J32: 廖方萍 | K32: 45908 | L32: 手工翻两角袋盖*2 | M32: 286
A33: 隆昌缝制五组 | B33: AAV10281 | C33: 正黑色 | D33: 2XL | F33: 48 | G33: 平车折订左手心袋布腰口橡筋挂耳连剪断 | H33: 45 | I33: 6921 | J33: 张兴英 | K33: 45908 | L33: 手工实样点肶袋及袋盖位 | M33: 439
A34: 隆昌缝制五组 | B34: AAV10281 | C34: 正黑色 | D34: XL | F34: 59 | G34: 平车转角贴肶袋三边明线连转角重叠固定袋口两端*2 | H34: 4 | I34: 7736 | J34: 黄芬 | K34: 45908 | L34: 四线落底袋布合前袋布一周 | M34: 345
A35: 隆昌缝制五组 | B35: AAV10281 | C35: 正黑色 | D35: S | F35: 73 | G35: 平车合后浪后机头一段*1 | H35: 14 | I35: 8528 | J35: 肖金花 | K35: 45908 | L35: 四线锁腰头散口一周 | M35: 342
A36: 隆昌缝制五组 | B36: AAV10281 | C36: 正黑色 | D36: L | F36: 79 | G36: 平车排肶袋口一段 | H36: 7 | I36: 8792 | J36: 叶礼芬 | K36: 45908 | L36: 五线对位合侧缝 | M36: 407
A37: 隆昌缝制五组 | B37: AAV10281 | C37: 正黑色 | D37: S | F37: 60 | G37: 平车落肶袋盖连压袋盖线*2 | H37: 7 | I37: 00133 | J37: 张文淑 | K37: 45908 | L37: 五线对位合底浪*1 | M37: 321
A38: 隆昌缝制五组 | B38: AAV10281 | C38: 正黑色 | D38: XL | F38: 69 | G38: 平车订后中尺码标*1 | H38: 67 | I38: 00240 | J38: 曾星淑 | K38: 45908 | L38: 五线对位合后浪*1 | M38: 321
A39: 隆昌缝制五组 | B39: AAV10281 | C39: 军绿色 | D39: M | E39: 14 | F39: 25 | G39: 手工点橡筋中位*1 | H39: 76 | I39: 100565074 | J39: 谢本习 | K39: 45908 | L39: 五线合前浪*1 | M39: 321
A40: 隆昌缝制五组 | B40: 15C0196-翻单 | C40: 黑色 | D40: XL | E40: 69/870 | F40: 91 | G40: 打腰头后中枣*1 | H40: 169 | I40: 100565524 | J40: 黄显菊 | K40: 45908 | L40: 中查 | M40: 333
...

Sheet Sheet3
A1: 工序序号 | B1: 求和项:数量
A2: 17 | B2: 286 | C2: =VLOOKUP(A2,'AAV10281'!A:G,7,0) -> 29.3
A3: 18 | B3: 262 | C3: =VLOOKUP(A3,'AAV10281'!A:G,7,0) -> 16
A4: 25 | B4: 588 | C4: =VLOOKUP(A4,'AAV10281'!A:G,7,0) -> 2.9
A5: 27 | B5: 291 | C5: =VLOOKUP(A5,'AAV10281'!A:G,7,0) -> 39.8
A6: 29 | B6: 342 | C6: =VLOOKUP(A6,'AAV10281'!A:G,7,0) -> 6.8
A7: 30 | B7: 836 | C7: =VLOOKUP(A7,'AAV10281'!A:G,7,0) -> #N/A
A8: 36 | B8: 588 | C8: =VLOOKUP(A8,'AAV10281'!A:G,7,0) -> 26.8
A9: 39 | B9: 205 | C9: =VLOOKUP(A9,'AAV10281'!A:G,7,0) -> 27.3
A10: 41 | B10: 247 | C10: =VLOOKUP(A10,'AAV10281'!A:G,7,0) -> 49.4
A11: 42 | B11: 361 | C11: =VLOOKUP(A11,'AAV10281'!A:G,7,0) -> 10.3
A12: 45 | B12: 240 | C12: =VLOOKUP(A12,'AAV10281'!A:G,7,0) -> 28.4
A13: 46 | B13: 262 | C13: =VLOOKUP(A13,'AAV10281'!A:G,7,0) -> 33.8
... A42: 120 | B42: 333 | C42: =VLOOKUP(A42,'AAV10281'!A:G,7,0) -> 51.1
